[2024-11-05T14:49:46.430+0000] {local_task_job_runner.py:123} INFO - ::group::Pre task execution logs
[2024-11-05T14:49:46.477+0000] {taskinstance.py:2612} INFO - Dependencies all met for dep_context=non-requeueable deps ti=<TaskInstance: airbnb_data_pipeline.Upload_To_S3 manual__2024-11-05T14:49:09.752007+00:00 [queued]>
[2024-11-05T14:49:46.499+0000] {taskinstance.py:2612} INFO - Dependencies all met for dep_context=requeueable deps ti=<TaskInstance: airbnb_data_pipeline.Upload_To_S3 manual__2024-11-05T14:49:09.752007+00:00 [queued]>
[2024-11-05T14:49:46.500+0000] {taskinstance.py:2865} INFO - Starting attempt 1 of 1
[2024-11-05T14:49:46.531+0000] {taskinstance.py:2888} INFO - Executing <Task(PythonOperator): Upload_To_S3> on 2024-11-05 14:49:09.752007+00:00
[2024-11-05T14:49:46.545+0000] {warnings.py:112} WARNING - /home/***/.local/lib/python3.12/site-packages/***/task/task_runner/standard_task_runner.py:70: DeprecationWarning: This process (pid=1011) is multi-threaded, use of fork() may lead to deadlocks in the child.
  pid = os.fork()

[2024-11-05T14:49:46.549+0000] {standard_task_runner.py:72} INFO - Started process 1013 to run task
[2024-11-05T14:49:46.549+0000] {standard_task_runner.py:104} INFO - Running: ['***', 'tasks', 'run', 'airbnb_data_pipeline', 'Upload_To_S3', 'manual__2024-11-05T14:49:09.752007+00:00', '--job-id', '41', '--raw', '--subdir', 'DAGS_FOLDER/airbnb_dag.py', '--cfg-path', '/tmp/tmpgt1eqdee']
[2024-11-05T14:49:46.552+0000] {standard_task_runner.py:105} INFO - Job 41: Subtask Upload_To_S3
[2024-11-05T14:49:46.651+0000] {task_command.py:467} INFO - Running <TaskInstance: airbnb_data_pipeline.Upload_To_S3 manual__2024-11-05T14:49:09.752007+00:00 [running]> on host 552c70a48aab
[2024-11-05T14:49:46.839+0000] {taskinstance.py:3131} INFO - Exporting env vars: AIRFLOW_CTX_DAG_OWNER='***' AIRFLOW_CTX_DAG_ID='airbnb_data_pipeline' AIRFLOW_CTX_TASK_ID='Upload_To_S3' AIRFLOW_CTX_EXECUTION_DATE='2024-11-05T14:49:09.752007+00:00' AIRFLOW_CTX_TRY_NUMBER='1' AIRFLOW_CTX_DAG_RUN_ID='manual__2024-11-05T14:49:09.752007+00:00'
[2024-11-05T14:49:46.842+0000] {logging_mixin.py:190} INFO - Task instance is in running state
[2024-11-05T14:49:46.844+0000] {logging_mixin.py:190} INFO -  Previous state of the Task instance: queued
[2024-11-05T14:49:46.846+0000] {logging_mixin.py:190} INFO - Current task name:Upload_To_S3 state:running start_date:2024-11-05 14:49:46.478270+00:00
[2024-11-05T14:49:46.847+0000] {logging_mixin.py:190} INFO - Dag name:airbnb_data_pipeline and current dag run status:running
[2024-11-05T14:49:46.848+0000] {taskinstance.py:731} INFO - ::endgroup::
[2024-11-05T14:49:49.949+0000] {taskinstance.py:3310} ERROR - Task failed with exception
Traceback (most recent call last):
  File "/home/airflow/.local/lib/python3.12/site-packages/airflow/models/taskinstance.py", line 767, in _execute_task
    result = _execute_callable(context=context, **execute_callable_kwargs)
             ^^^^^^^^^^^^^^^^^^^^^^^^^^^^^^^^^^^^^^^^^^^^^^^^^^^^^^^^^^^^^
  File "/home/airflow/.local/lib/python3.12/site-packages/airflow/models/taskinstance.py", line 733, in _execute_callable
    return ExecutionCallableRunner(
           ^^^^^^^^^^^^^^^^^^^^^^^^
  File "/home/airflow/.local/lib/python3.12/site-packages/airflow/utils/operator_helpers.py", line 252, in run
    return self.func(*args, **kwargs)
           ^^^^^^^^^^^^^^^^^^^^^^^^^^
  File "/home/airflow/.local/lib/python3.12/site-packages/airflow/models/baseoperator.py", line 406, in wrapper
    return func(self, *args, **kwargs)
           ^^^^^^^^^^^^^^^^^^^^^^^^^^^
  File "/home/airflow/.local/lib/python3.12/site-packages/airflow/operators/python.py", line 238, in execute
    return_value = self.execute_callable()
                   ^^^^^^^^^^^^^^^^^^^^^^^
  File "/home/airflow/.local/lib/python3.12/site-packages/airflow/operators/python.py", line 256, in execute_callable
    return runner.run(*self.op_args, **self.op_kwargs)
           ^^^^^^^^^^^^^^^^^^^^^^^^^^^^^^^^^^^^^^^^^^^
  File "/home/airflow/.local/lib/python3.12/site-packages/airflow/utils/operator_helpers.py", line 252, in run
    return self.func(*args, **kwargs)
           ^^^^^^^^^^^^^^^^^^^^^^^^^^
  File "/opt/airflow/dags/etl/s3_upload_etl.py", line 23, in upload_file
    response = s3_client.upload_file(file_name, bucket, object_name)
               ^^^^^^^^^^^^^^^^^^^^^^^^^^^^^^^^^^^^^^^^^^^^^^^^^^^^^
  File "/home/airflow/.local/lib/python3.12/site-packages/boto3/s3/inject.py", line 145, in upload_file
    return transfer.upload_file(
           ^^^^^^^^^^^^^^^^^^^^^
  File "/home/airflow/.local/lib/python3.12/site-packages/boto3/s3/transfer.py", line 372, in upload_file
    future.result()
  File "/home/airflow/.local/lib/python3.12/site-packages/s3transfer/futures.py", line 103, in result
    return self._coordinator.result()
           ^^^^^^^^^^^^^^^^^^^^^^^^^^
  File "/home/airflow/.local/lib/python3.12/site-packages/s3transfer/futures.py", line 266, in result
    raise self._exception
  File "/home/airflow/.local/lib/python3.12/site-packages/s3transfer/tasks.py", line 269, in _main
    self._submit(transfer_future=transfer_future, **kwargs)
  File "/home/airflow/.local/lib/python3.12/site-packages/s3transfer/upload.py", line 591, in _submit
    upload_input_manager.provide_transfer_size(transfer_future)
  File "/home/airflow/.local/lib/python3.12/site-packages/s3transfer/upload.py", line 244, in provide_transfer_size
    self._osutil.get_file_size(transfer_future.meta.call_args.fileobj)
  File "/home/airflow/.local/lib/python3.12/site-packages/s3transfer/utils.py", line 256, in get_file_size
    return os.path.getsize(filename)
           ^^^^^^^^^^^^^^^^^^^^^^^^^
  File "<frozen genericpath>", line 62, in getsize
FileNotFoundError: [Errno 2] No such file or directory: 'amsterdam_2024-09-05_listings.csv'
[2024-11-05T14:49:50.004+0000] {logging_mixin.py:190} INFO - Task instance in failure state
[2024-11-05T14:49:50.006+0000] {logging_mixin.py:190} INFO - Task start:2024-11-05 14:49:46.478270+00:00 end:2024-11-05 14:49:50.003248+00:00 duration:3.524978
[2024-11-05T14:49:50.008+0000] {logging_mixin.py:190} INFO - Task:<Task(PythonOperator): Upload_To_S3> dag:<DAG: airbnb_data_pipeline> dagrun:<DagRun airbnb_data_pipeline @ 2024-11-05 14:49:09.752007+00:00: manual__2024-11-05T14:49:09.752007+00:00, state:running, queued_at: 2024-11-05 14:49:09.923653+00:00. externally triggered: True>
[2024-11-05T14:49:50.009+0000] {logging_mixin.py:190} INFO - Failure caused by [Errno 2] No such file or directory: 'amsterdam_2024-09-05_listings.csv'
[2024-11-05T14:49:50.011+0000] {taskinstance.py:1225} INFO - Marking task as FAILED. dag_id=airbnb_data_pipeline, task_id=Upload_To_S3, run_id=manual__2024-11-05T14:49:09.752007+00:00, execution_date=20241105T144909, start_date=20241105T144946, end_date=20241105T144950
[2024-11-05T14:49:50.064+0000] {taskinstance.py:340} INFO - ::group::Post task execution logs
[2024-11-05T14:49:50.066+0000] {standard_task_runner.py:124} ERROR - Failed to execute job 41 for task Upload_To_S3 ([Errno 2] No such file or directory: 'amsterdam_2024-09-05_listings.csv'; 1013)
Traceback (most recent call last):
  File "/home/airflow/.local/lib/python3.12/site-packages/airflow/task/task_runner/standard_task_runner.py", line 117, in _start_by_fork
    ret = args.func(args, dag=self.dag)
          ^^^^^^^^^^^^^^^^^^^^^^^^^^^^^
  File "/home/airflow/.local/lib/python3.12/site-packages/airflow/cli/cli_config.py", line 49, in command
    return func(*args, **kwargs)
           ^^^^^^^^^^^^^^^^^^^^^
  File "/home/airflow/.local/lib/python3.12/site-packages/airflow/utils/cli.py", line 115, in wrapper
    return f(*args, **kwargs)
           ^^^^^^^^^^^^^^^^^^
  File "/home/airflow/.local/lib/python3.12/site-packages/airflow/cli/commands/task_command.py", line 483, in task_run
    task_return_code = _run_task_by_selected_method(args, _dag, ti)
                       ^^^^^^^^^^^^^^^^^^^^^^^^^^^^^^^^^^^^^^^^^^^^
  File "/home/airflow/.local/lib/python3.12/site-packages/airflow/cli/commands/task_command.py", line 256, in _run_task_by_selected_method
    return _run_raw_task(args, ti)
           ^^^^^^^^^^^^^^^^^^^^^^^
  File "/home/airflow/.local/lib/python3.12/site-packages/airflow/cli/commands/task_command.py", line 341, in _run_raw_task
    return ti._run_raw_task(
           ^^^^^^^^^^^^^^^^^
  File "/home/airflow/.local/lib/python3.12/site-packages/airflow/utils/session.py", line 97, in wrapper
    return func(*args, session=session, **kwargs)
           ^^^^^^^^^^^^^^^^^^^^^^^^^^^^^^^^^^^^^^
  File "/home/airflow/.local/lib/python3.12/site-packages/airflow/models/taskinstance.py", line 3004, in _run_raw_task
    return _run_raw_task(
           ^^^^^^^^^^^^^^
  File "/home/airflow/.local/lib/python3.12/site-packages/airflow/models/taskinstance.py", line 273, in _run_raw_task
    TaskInstance._execute_task_with_callbacks(
  File "/home/airflow/.local/lib/python3.12/site-packages/airflow/models/taskinstance.py", line 3158, in _execute_task_with_callbacks
    result = self._execute_task(context, task_orig)
             ^^^^^^^^^^^^^^^^^^^^^^^^^^^^^^^^^^^^^^
  File "/home/airflow/.local/lib/python3.12/site-packages/airflow/models/taskinstance.py", line 3182, in _execute_task
    return _execute_task(self, context, task_orig)
           ^^^^^^^^^^^^^^^^^^^^^^^^^^^^^^^^^^^^^^^
  File "/home/airflow/.local/lib/python3.12/site-packages/airflow/models/taskinstance.py", line 767, in _execute_task
    result = _execute_callable(context=context, **execute_callable_kwargs)
             ^^^^^^^^^^^^^^^^^^^^^^^^^^^^^^^^^^^^^^^^^^^^^^^^^^^^^^^^^^^^^
  File "/home/airflow/.local/lib/python3.12/site-packages/airflow/models/taskinstance.py", line 733, in _execute_callable
    return ExecutionCallableRunner(
           ^^^^^^^^^^^^^^^^^^^^^^^^
  File "/home/airflow/.local/lib/python3.12/site-packages/airflow/utils/operator_helpers.py", line 252, in run
    return self.func(*args, **kwargs)
           ^^^^^^^^^^^^^^^^^^^^^^^^^^
  File "/home/airflow/.local/lib/python3.12/site-packages/airflow/models/baseoperator.py", line 406, in wrapper
    return func(self, *args, **kwargs)
           ^^^^^^^^^^^^^^^^^^^^^^^^^^^
  File "/home/airflow/.local/lib/python3.12/site-packages/airflow/operators/python.py", line 238, in execute
    return_value = self.execute_callable()
                   ^^^^^^^^^^^^^^^^^^^^^^^
  File "/home/airflow/.local/lib/python3.12/site-packages/airflow/operators/python.py", line 256, in execute_callable
    return runner.run(*self.op_args, **self.op_kwargs)
           ^^^^^^^^^^^^^^^^^^^^^^^^^^^^^^^^^^^^^^^^^^^
  File "/home/airflow/.local/lib/python3.12/site-packages/airflow/utils/operator_helpers.py", line 252, in run
    return self.func(*args, **kwargs)
           ^^^^^^^^^^^^^^^^^^^^^^^^^^
  File "/opt/airflow/dags/etl/s3_upload_etl.py", line 23, in upload_file
    response = s3_client.upload_file(file_name, bucket, object_name)
               ^^^^^^^^^^^^^^^^^^^^^^^^^^^^^^^^^^^^^^^^^^^^^^^^^^^^^
  File "/home/airflow/.local/lib/python3.12/site-packages/boto3/s3/inject.py", line 145, in upload_file
    return transfer.upload_file(
           ^^^^^^^^^^^^^^^^^^^^^
  File "/home/airflow/.local/lib/python3.12/site-packages/boto3/s3/transfer.py", line 372, in upload_file
    future.result()
  File "/home/airflow/.local/lib/python3.12/site-packages/s3transfer/futures.py", line 103, in result
    return self._coordinator.result()
           ^^^^^^^^^^^^^^^^^^^^^^^^^^
  File "/home/airflow/.local/lib/python3.12/site-packages/s3transfer/futures.py", line 266, in result
    raise self._exception
  File "/home/airflow/.local/lib/python3.12/site-packages/s3transfer/tasks.py", line 269, in _main
    self._submit(transfer_future=transfer_future, **kwargs)
  File "/home/airflow/.local/lib/python3.12/site-packages/s3transfer/upload.py", line 591, in _submit
    upload_input_manager.provide_transfer_size(transfer_future)
  File "/home/airflow/.local/lib/python3.12/site-packages/s3transfer/upload.py", line 244, in provide_transfer_size
    self._osutil.get_file_size(transfer_future.meta.call_args.fileobj)
  File "/home/airflow/.local/lib/python3.12/site-packages/s3transfer/utils.py", line 256, in get_file_size
    return os.path.getsize(filename)
           ^^^^^^^^^^^^^^^^^^^^^^^^^
  File "<frozen genericpath>", line 62, in getsize
FileNotFoundError: [Errno 2] No such file or directory: 'amsterdam_2024-09-05_listings.csv'
[2024-11-05T14:49:50.152+0000] {local_task_job_runner.py:266} INFO - Task exited with return code 1
[2024-11-05T14:49:50.203+0000] {taskinstance.py:3900} INFO - 0 downstream tasks scheduled from follow-on schedule check
[2024-11-05T14:49:50.207+0000] {local_task_job_runner.py:245} INFO - ::endgroup::
